{
 "cells": [
  {
   "cell_type": "code",
   "execution_count": null,
   "metadata": {},
   "outputs": [
    {
     "name": "stderr",
     "output_type": "stream",
     "text": [
      "\n",
      "A module that was compiled using NumPy 1.x cannot be run in\n",
      "NumPy 2.2.1 as it may crash. To support both 1.x and 2.x\n",
      "versions of NumPy, modules must be compiled with NumPy 2.0.\n",
      "Some module may need to rebuild instead e.g. with 'pybind11>=2.12'.\n",
      "\n",
      "If you are a user of the module, the easiest solution will be to\n",
      "downgrade to 'numpy<2' or try to upgrade the affected module.\n",
      "We expect that some modules will need time to support NumPy 2.\n",
      "\n",
      "Traceback (most recent call last):  File \"<frozen runpy>\", line 198, in _run_module_as_main\n",
      "  File \"<frozen runpy>\", line 88, in _run_code\n",
      "  File \"C:\\Users\\vaibhavi\\anaconda3\\Lib\\site-packages\\ipykernel_launcher.py\", line 17, in <module>\n",
      "    app.launch_new_instance()\n",
      "  File \"C:\\Users\\vaibhavi\\anaconda3\\Lib\\site-packages\\traitlets\\config\\application.py\", line 1075, in launch_instance\n",
      "    app.start()\n",
      "  File \"C:\\Users\\vaibhavi\\anaconda3\\Lib\\site-packages\\ipykernel\\kernelapp.py\", line 701, in start\n",
      "    self.io_loop.start()\n",
      "  File \"C:\\Users\\vaibhavi\\anaconda3\\Lib\\site-packages\\tornado\\platform\\asyncio.py\", line 205, in start\n",
      "    self.asyncio_loop.run_forever()\n",
      "  File \"C:\\Users\\vaibhavi\\anaconda3\\Lib\\asyncio\\windows_events.py\", line 322, in run_forever\n",
      "    super().run_forever()\n",
      "  File \"C:\\Users\\vaibhavi\\anaconda3\\Lib\\asyncio\\base_events.py\", line 641, in run_forever\n",
      "    self._run_once()\n",
      "  File \"C:\\Users\\vaibhavi\\anaconda3\\Lib\\asyncio\\base_events.py\", line 1986, in _run_once\n",
      "    handle._run()\n",
      "  File \"C:\\Users\\vaibhavi\\anaconda3\\Lib\\asyncio\\events.py\", line 88, in _run\n",
      "    self._context.run(self._callback, *self._args)\n",
      "  File \"C:\\Users\\vaibhavi\\anaconda3\\Lib\\site-packages\\ipykernel\\kernelbase.py\", line 534, in dispatch_queue\n",
      "    await self.process_one()\n",
      "  File \"C:\\Users\\vaibhavi\\anaconda3\\Lib\\site-packages\\ipykernel\\kernelbase.py\", line 523, in process_one\n",
      "    await dispatch(*args)\n",
      "  File \"C:\\Users\\vaibhavi\\anaconda3\\Lib\\site-packages\\ipykernel\\kernelbase.py\", line 429, in dispatch_shell\n",
      "    await result\n",
      "  File \"C:\\Users\\vaibhavi\\anaconda3\\Lib\\site-packages\\ipykernel\\kernelbase.py\", line 767, in execute_request\n",
      "    reply_content = await reply_content\n",
      "  File \"C:\\Users\\vaibhavi\\anaconda3\\Lib\\site-packages\\ipykernel\\ipkernel.py\", line 429, in do_execute\n",
      "    res = shell.run_cell(\n",
      "  File \"C:\\Users\\vaibhavi\\anaconda3\\Lib\\site-packages\\ipykernel\\zmqshell.py\", line 549, in run_cell\n",
      "    return super().run_cell(*args, **kwargs)\n",
      "  File \"C:\\Users\\vaibhavi\\anaconda3\\Lib\\site-packages\\IPython\\core\\interactiveshell.py\", line 3075, in run_cell\n",
      "    result = self._run_cell(\n",
      "  File \"C:\\Users\\vaibhavi\\anaconda3\\Lib\\site-packages\\IPython\\core\\interactiveshell.py\", line 3130, in _run_cell\n",
      "    result = runner(coro)\n",
      "  File \"C:\\Users\\vaibhavi\\anaconda3\\Lib\\site-packages\\IPython\\core\\async_helpers.py\", line 128, in _pseudo_sync_runner\n",
      "    coro.send(None)\n",
      "  File \"C:\\Users\\vaibhavi\\anaconda3\\Lib\\site-packages\\IPython\\core\\interactiveshell.py\", line 3334, in run_cell_async\n",
      "    has_raised = await self.run_ast_nodes(code_ast.body, cell_name,\n",
      "  File \"C:\\Users\\vaibhavi\\anaconda3\\Lib\\site-packages\\IPython\\core\\interactiveshell.py\", line 3517, in run_ast_nodes\n",
      "    if await self.run_code(code, result, async_=asy):\n",
      "  File \"C:\\Users\\vaibhavi\\anaconda3\\Lib\\site-packages\\IPython\\core\\interactiveshell.py\", line 3577, in run_code\n",
      "    exec(code_obj, self.user_global_ns, self.user_ns)\n",
      "  File \"C:\\Users\\vaibhavi\\AppData\\Local\\Temp\\ipykernel_27692\\3143499411.py\", line 5, in <module>\n",
      "    import pandas as pd\n",
      "  File \"C:\\Users\\vaibhavi\\AppData\\Roaming\\Python\\Python312\\site-packages\\pandas\\__init__.py\", line 39, in <module>\n",
      "    from pandas.compat import (\n",
      "  File \"C:\\Users\\vaibhavi\\AppData\\Roaming\\Python\\Python312\\site-packages\\pandas\\compat\\__init__.py\", line 27, in <module>\n",
      "    from pandas.compat.pyarrow import (\n",
      "  File \"C:\\Users\\vaibhavi\\AppData\\Roaming\\Python\\Python312\\site-packages\\pandas\\compat\\pyarrow.py\", line 8, in <module>\n",
      "    import pyarrow as pa\n",
      "  File \"C:\\Users\\vaibhavi\\anaconda3\\Lib\\site-packages\\pyarrow\\__init__.py\", line 65, in <module>\n",
      "    import pyarrow.lib as _lib\n"
     ]
    },
    {
     "ename": "ImportError",
     "evalue": "\nA module that was compiled using NumPy 1.x cannot be run in\nNumPy 2.2.1 as it may crash. To support both 1.x and 2.x\nversions of NumPy, modules must be compiled with NumPy 2.0.\nSome module may need to rebuild instead e.g. with 'pybind11>=2.12'.\n\nIf you are a user of the module, the easiest solution will be to\ndowngrade to 'numpy<2' or try to upgrade the affected module.\nWe expect that some modules will need time to support NumPy 2.\n\n",
     "output_type": "error",
     "traceback": [
      "\u001b[1;31m---------------------------------------------------------------------------\u001b[0m",
      "\u001b[1;31mImportError\u001b[0m                               Traceback (most recent call last)",
      "File \u001b[1;32m~\\AppData\\Roaming\\Python\\Python312\\site-packages\\numpy\\core\\_multiarray_umath.py:44\u001b[0m, in \u001b[0;36m__getattr__\u001b[1;34m(attr_name)\u001b[0m\n\u001b[0;32m     39\u001b[0m     \u001b[38;5;66;03m# Also print the message (with traceback).  This is because old versions\u001b[39;00m\n\u001b[0;32m     40\u001b[0m     \u001b[38;5;66;03m# of NumPy unfortunately set up the import to replace (and hide) the\u001b[39;00m\n\u001b[0;32m     41\u001b[0m     \u001b[38;5;66;03m# error.  The traceback shouldn't be needed, but e.g. pytest plugins\u001b[39;00m\n\u001b[0;32m     42\u001b[0m     \u001b[38;5;66;03m# seem to swallow it and we should be failing anyway...\u001b[39;00m\n\u001b[0;32m     43\u001b[0m     sys\u001b[38;5;241m.\u001b[39mstderr\u001b[38;5;241m.\u001b[39mwrite(msg \u001b[38;5;241m+\u001b[39m tb_msg)\n\u001b[1;32m---> 44\u001b[0m     \u001b[38;5;28;01mraise\u001b[39;00m \u001b[38;5;167;01mImportError\u001b[39;00m(msg)\n\u001b[0;32m     46\u001b[0m ret \u001b[38;5;241m=\u001b[39m \u001b[38;5;28mgetattr\u001b[39m(_multiarray_umath, attr_name, \u001b[38;5;28;01mNone\u001b[39;00m)\n\u001b[0;32m     47\u001b[0m \u001b[38;5;28;01mif\u001b[39;00m ret \u001b[38;5;129;01mis\u001b[39;00m \u001b[38;5;28;01mNone\u001b[39;00m:\n",
      "\u001b[1;31mImportError\u001b[0m: \nA module that was compiled using NumPy 1.x cannot be run in\nNumPy 2.2.1 as it may crash. To support both 1.x and 2.x\nversions of NumPy, modules must be compiled with NumPy 2.0.\nSome module may need to rebuild instead e.g. with 'pybind11>=2.12'.\n\nIf you are a user of the module, the easiest solution will be to\ndowngrade to 'numpy<2' or try to upgrade the affected module.\nWe expect that some modules will need time to support NumPy 2.\n\n"
     ]
    },
    {
     "name": "stderr",
     "output_type": "stream",
     "text": [
      "\n",
      "A module that was compiled using NumPy 1.x cannot be run in\n",
      "NumPy 2.2.1 as it may crash. To support both 1.x and 2.x\n",
      "versions of NumPy, modules must be compiled with NumPy 2.0.\n",
      "Some module may need to rebuild instead e.g. with 'pybind11>=2.12'.\n",
      "\n",
      "If you are a user of the module, the easiest solution will be to\n",
      "downgrade to 'numpy<2' or try to upgrade the affected module.\n",
      "We expect that some modules will need time to support NumPy 2.\n",
      "\n",
      "Traceback (most recent call last):  File \"<frozen runpy>\", line 198, in _run_module_as_main\n",
      "  File \"<frozen runpy>\", line 88, in _run_code\n",
      "  File \"C:\\Users\\vaibhavi\\anaconda3\\Lib\\site-packages\\ipykernel_launcher.py\", line 17, in <module>\n",
      "    app.launch_new_instance()\n",
      "  File \"C:\\Users\\vaibhavi\\anaconda3\\Lib\\site-packages\\traitlets\\config\\application.py\", line 1075, in launch_instance\n",
      "    app.start()\n",
      "  File \"C:\\Users\\vaibhavi\\anaconda3\\Lib\\site-packages\\ipykernel\\kernelapp.py\", line 701, in start\n",
      "    self.io_loop.start()\n",
      "  File \"C:\\Users\\vaibhavi\\anaconda3\\Lib\\site-packages\\tornado\\platform\\asyncio.py\", line 205, in start\n",
      "    self.asyncio_loop.run_forever()\n",
      "  File \"C:\\Users\\vaibhavi\\anaconda3\\Lib\\asyncio\\windows_events.py\", line 322, in run_forever\n",
      "    super().run_forever()\n",
      "  File \"C:\\Users\\vaibhavi\\anaconda3\\Lib\\asyncio\\base_events.py\", line 641, in run_forever\n",
      "    self._run_once()\n",
      "  File \"C:\\Users\\vaibhavi\\anaconda3\\Lib\\asyncio\\base_events.py\", line 1986, in _run_once\n",
      "    handle._run()\n",
      "  File \"C:\\Users\\vaibhavi\\anaconda3\\Lib\\asyncio\\events.py\", line 88, in _run\n",
      "    self._context.run(self._callback, *self._args)\n",
      "  File \"C:\\Users\\vaibhavi\\anaconda3\\Lib\\site-packages\\ipykernel\\kernelbase.py\", line 534, in dispatch_queue\n",
      "    await self.process_one()\n",
      "  File \"C:\\Users\\vaibhavi\\anaconda3\\Lib\\site-packages\\ipykernel\\kernelbase.py\", line 523, in process_one\n",
      "    await dispatch(*args)\n",
      "  File \"C:\\Users\\vaibhavi\\anaconda3\\Lib\\site-packages\\ipykernel\\kernelbase.py\", line 429, in dispatch_shell\n",
      "    await result\n",
      "  File \"C:\\Users\\vaibhavi\\anaconda3\\Lib\\site-packages\\ipykernel\\kernelbase.py\", line 767, in execute_request\n",
      "    reply_content = await reply_content\n",
      "  File \"C:\\Users\\vaibhavi\\anaconda3\\Lib\\site-packages\\ipykernel\\ipkernel.py\", line 429, in do_execute\n",
      "    res = shell.run_cell(\n",
      "  File \"C:\\Users\\vaibhavi\\anaconda3\\Lib\\site-packages\\ipykernel\\zmqshell.py\", line 549, in run_cell\n",
      "    return super().run_cell(*args, **kwargs)\n",
      "  File \"C:\\Users\\vaibhavi\\anaconda3\\Lib\\site-packages\\IPython\\core\\interactiveshell.py\", line 3075, in run_cell\n",
      "    result = self._run_cell(\n",
      "  File \"C:\\Users\\vaibhavi\\anaconda3\\Lib\\site-packages\\IPython\\core\\interactiveshell.py\", line 3130, in _run_cell\n",
      "    result = runner(coro)\n",
      "  File \"C:\\Users\\vaibhavi\\anaconda3\\Lib\\site-packages\\IPython\\core\\async_helpers.py\", line 128, in _pseudo_sync_runner\n",
      "    coro.send(None)\n",
      "  File \"C:\\Users\\vaibhavi\\anaconda3\\Lib\\site-packages\\IPython\\core\\interactiveshell.py\", line 3334, in run_cell_async\n",
      "    has_raised = await self.run_ast_nodes(code_ast.body, cell_name,\n",
      "  File \"C:\\Users\\vaibhavi\\anaconda3\\Lib\\site-packages\\IPython\\core\\interactiveshell.py\", line 3517, in run_ast_nodes\n",
      "    if await self.run_code(code, result, async_=asy):\n",
      "  File \"C:\\Users\\vaibhavi\\anaconda3\\Lib\\site-packages\\IPython\\core\\interactiveshell.py\", line 3577, in run_code\n",
      "    exec(code_obj, self.user_global_ns, self.user_ns)\n",
      "  File \"C:\\Users\\vaibhavi\\AppData\\Local\\Temp\\ipykernel_27692\\3143499411.py\", line 5, in <module>\n",
      "    import pandas as pd\n",
      "  File \"C:\\Users\\vaibhavi\\AppData\\Roaming\\Python\\Python312\\site-packages\\pandas\\__init__.py\", line 62, in <module>\n",
      "    from pandas.core.api import (\n",
      "  File \"C:\\Users\\vaibhavi\\AppData\\Roaming\\Python\\Python312\\site-packages\\pandas\\core\\api.py\", line 9, in <module>\n",
      "    from pandas.core.dtypes.dtypes import (\n",
      "  File \"C:\\Users\\vaibhavi\\AppData\\Roaming\\Python\\Python312\\site-packages\\pandas\\core\\dtypes\\dtypes.py\", line 24, in <module>\n",
      "    from pandas._libs import (\n",
      "  File \"C:\\Users\\vaibhavi\\anaconda3\\Lib\\site-packages\\pyarrow\\__init__.py\", line 65, in <module>\n",
      "    import pyarrow.lib as _lib\n"
     ]
    },
    {
     "ename": "ImportError",
     "evalue": "\nA module that was compiled using NumPy 1.x cannot be run in\nNumPy 2.2.1 as it may crash. To support both 1.x and 2.x\nversions of NumPy, modules must be compiled with NumPy 2.0.\nSome module may need to rebuild instead e.g. with 'pybind11>=2.12'.\n\nIf you are a user of the module, the easiest solution will be to\ndowngrade to 'numpy<2' or try to upgrade the affected module.\nWe expect that some modules will need time to support NumPy 2.\n\n",
     "output_type": "error",
     "traceback": [
      "\u001b[1;31m---------------------------------------------------------------------------\u001b[0m",
      "\u001b[1;31mImportError\u001b[0m                               Traceback (most recent call last)",
      "File \u001b[1;32m~\\AppData\\Roaming\\Python\\Python312\\site-packages\\numpy\\core\\_multiarray_umath.py:44\u001b[0m, in \u001b[0;36m__getattr__\u001b[1;34m(attr_name)\u001b[0m\n\u001b[0;32m     39\u001b[0m     \u001b[38;5;66;03m# Also print the message (with traceback).  This is because old versions\u001b[39;00m\n\u001b[0;32m     40\u001b[0m     \u001b[38;5;66;03m# of NumPy unfortunately set up the import to replace (and hide) the\u001b[39;00m\n\u001b[0;32m     41\u001b[0m     \u001b[38;5;66;03m# error.  The traceback shouldn't be needed, but e.g. pytest plugins\u001b[39;00m\n\u001b[0;32m     42\u001b[0m     \u001b[38;5;66;03m# seem to swallow it and we should be failing anyway...\u001b[39;00m\n\u001b[0;32m     43\u001b[0m     sys\u001b[38;5;241m.\u001b[39mstderr\u001b[38;5;241m.\u001b[39mwrite(msg \u001b[38;5;241m+\u001b[39m tb_msg)\n\u001b[1;32m---> 44\u001b[0m     \u001b[38;5;28;01mraise\u001b[39;00m \u001b[38;5;167;01mImportError\u001b[39;00m(msg)\n\u001b[0;32m     46\u001b[0m ret \u001b[38;5;241m=\u001b[39m \u001b[38;5;28mgetattr\u001b[39m(_multiarray_umath, attr_name, \u001b[38;5;28;01mNone\u001b[39;00m)\n\u001b[0;32m     47\u001b[0m \u001b[38;5;28;01mif\u001b[39;00m ret \u001b[38;5;129;01mis\u001b[39;00m \u001b[38;5;28;01mNone\u001b[39;00m:\n",
      "\u001b[1;31mImportError\u001b[0m: \nA module that was compiled using NumPy 1.x cannot be run in\nNumPy 2.2.1 as it may crash. To support both 1.x and 2.x\nversions of NumPy, modules must be compiled with NumPy 2.0.\nSome module may need to rebuild instead e.g. with 'pybind11>=2.12'.\n\nIf you are a user of the module, the easiest solution will be to\ndowngrade to 'numpy<2' or try to upgrade the affected module.\nWe expect that some modules will need time to support NumPy 2.\n\n"
     ]
    },
    {
     "name": "stderr",
     "output_type": "stream",
     "text": [
      "\n",
      "A module that was compiled using NumPy 1.x cannot be run in\n",
      "NumPy 2.2.1 as it may crash. To support both 1.x and 2.x\n",
      "versions of NumPy, modules must be compiled with NumPy 2.0.\n",
      "Some module may need to rebuild instead e.g. with 'pybind11>=2.12'.\n",
      "\n",
      "If you are a user of the module, the easiest solution will be to\n",
      "downgrade to 'numpy<2' or try to upgrade the affected module.\n",
      "We expect that some modules will need time to support NumPy 2.\n",
      "\n",
      "Traceback (most recent call last):  File \"<frozen runpy>\", line 198, in _run_module_as_main\n",
      "  File \"<frozen runpy>\", line 88, in _run_code\n",
      "  File \"C:\\Users\\vaibhavi\\anaconda3\\Lib\\site-packages\\ipykernel_launcher.py\", line 17, in <module>\n",
      "    app.launch_new_instance()\n",
      "  File \"C:\\Users\\vaibhavi\\anaconda3\\Lib\\site-packages\\traitlets\\config\\application.py\", line 1075, in launch_instance\n",
      "    app.start()\n",
      "  File \"C:\\Users\\vaibhavi\\anaconda3\\Lib\\site-packages\\ipykernel\\kernelapp.py\", line 701, in start\n",
      "    self.io_loop.start()\n",
      "  File \"C:\\Users\\vaibhavi\\anaconda3\\Lib\\site-packages\\tornado\\platform\\asyncio.py\", line 205, in start\n",
      "    self.asyncio_loop.run_forever()\n",
      "  File \"C:\\Users\\vaibhavi\\anaconda3\\Lib\\asyncio\\windows_events.py\", line 322, in run_forever\n",
      "    super().run_forever()\n",
      "  File \"C:\\Users\\vaibhavi\\anaconda3\\Lib\\asyncio\\base_events.py\", line 641, in run_forever\n",
      "    self._run_once()\n",
      "  File \"C:\\Users\\vaibhavi\\anaconda3\\Lib\\asyncio\\base_events.py\", line 1986, in _run_once\n",
      "    handle._run()\n",
      "  File \"C:\\Users\\vaibhavi\\anaconda3\\Lib\\asyncio\\events.py\", line 88, in _run\n",
      "    self._context.run(self._callback, *self._args)\n",
      "  File \"C:\\Users\\vaibhavi\\anaconda3\\Lib\\site-packages\\ipykernel\\kernelbase.py\", line 534, in dispatch_queue\n",
      "    await self.process_one()\n",
      "  File \"C:\\Users\\vaibhavi\\anaconda3\\Lib\\site-packages\\ipykernel\\kernelbase.py\", line 523, in process_one\n",
      "    await dispatch(*args)\n",
      "  File \"C:\\Users\\vaibhavi\\anaconda3\\Lib\\site-packages\\ipykernel\\kernelbase.py\", line 429, in dispatch_shell\n",
      "    await result\n",
      "  File \"C:\\Users\\vaibhavi\\anaconda3\\Lib\\site-packages\\ipykernel\\kernelbase.py\", line 767, in execute_request\n",
      "    reply_content = await reply_content\n",
      "  File \"C:\\Users\\vaibhavi\\anaconda3\\Lib\\site-packages\\ipykernel\\ipkernel.py\", line 429, in do_execute\n",
      "    res = shell.run_cell(\n",
      "  File \"C:\\Users\\vaibhavi\\anaconda3\\Lib\\site-packages\\ipykernel\\zmqshell.py\", line 549, in run_cell\n",
      "    return super().run_cell(*args, **kwargs)\n",
      "  File \"C:\\Users\\vaibhavi\\anaconda3\\Lib\\site-packages\\IPython\\core\\interactiveshell.py\", line 3075, in run_cell\n",
      "    result = self._run_cell(\n",
      "  File \"C:\\Users\\vaibhavi\\anaconda3\\Lib\\site-packages\\IPython\\core\\interactiveshell.py\", line 3130, in _run_cell\n",
      "    result = runner(coro)\n",
      "  File \"C:\\Users\\vaibhavi\\anaconda3\\Lib\\site-packages\\IPython\\core\\async_helpers.py\", line 128, in _pseudo_sync_runner\n",
      "    coro.send(None)\n",
      "  File \"C:\\Users\\vaibhavi\\anaconda3\\Lib\\site-packages\\IPython\\core\\interactiveshell.py\", line 3334, in run_cell_async\n",
      "    has_raised = await self.run_ast_nodes(code_ast.body, cell_name,\n",
      "  File \"C:\\Users\\vaibhavi\\anaconda3\\Lib\\site-packages\\IPython\\core\\interactiveshell.py\", line 3517, in run_ast_nodes\n",
      "    if await self.run_code(code, result, async_=asy):\n",
      "  File \"C:\\Users\\vaibhavi\\anaconda3\\Lib\\site-packages\\IPython\\core\\interactiveshell.py\", line 3577, in run_code\n",
      "    exec(code_obj, self.user_global_ns, self.user_ns)\n",
      "  File \"C:\\Users\\vaibhavi\\AppData\\Local\\Temp\\ipykernel_27692\\3143499411.py\", line 5, in <module>\n",
      "    import pandas as pd\n",
      "  File \"C:\\Users\\vaibhavi\\AppData\\Roaming\\Python\\Python312\\site-packages\\pandas\\__init__.py\", line 62, in <module>\n",
      "    from pandas.core.api import (\n",
      "  File \"C:\\Users\\vaibhavi\\AppData\\Roaming\\Python\\Python312\\site-packages\\pandas\\core\\api.py\", line 28, in <module>\n",
      "    from pandas.core.arrays import Categorical\n",
      "  File \"C:\\Users\\vaibhavi\\AppData\\Roaming\\Python\\Python312\\site-packages\\pandas\\core\\arrays\\__init__.py\", line 1, in <module>\n",
      "    from pandas.core.arrays.arrow import ArrowExtensionArray\n",
      "  File \"C:\\Users\\vaibhavi\\AppData\\Roaming\\Python\\Python312\\site-packages\\pandas\\core\\arrays\\arrow\\__init__.py\", line 5, in <module>\n",
      "    from pandas.core.arrays.arrow.array import ArrowExtensionArray\n",
      "  File \"C:\\Users\\vaibhavi\\AppData\\Roaming\\Python\\Python312\\site-packages\\pandas\\core\\arrays\\arrow\\array.py\", line 50, in <module>\n",
      "    from pandas.core import (\n",
      "  File \"C:\\Users\\vaibhavi\\AppData\\Roaming\\Python\\Python312\\site-packages\\pandas\\core\\ops\\__init__.py\", line 8, in <module>\n",
      "    from pandas.core.ops.array_ops import (\n",
      "  File \"C:\\Users\\vaibhavi\\AppData\\Roaming\\Python\\Python312\\site-packages\\pandas\\core\\ops\\array_ops.py\", line 56, in <module>\n",
      "    from pandas.core.computation import expressions\n",
      "  File \"C:\\Users\\vaibhavi\\AppData\\Roaming\\Python\\Python312\\site-packages\\pandas\\core\\computation\\expressions.py\", line 21, in <module>\n",
      "    from pandas.core.computation.check import NUMEXPR_INSTALLED\n",
      "  File \"C:\\Users\\vaibhavi\\AppData\\Roaming\\Python\\Python312\\site-packages\\pandas\\core\\computation\\check.py\", line 5, in <module>\n",
      "    ne = import_optional_dependency(\"numexpr\", errors=\"warn\")\n",
      "  File \"C:\\Users\\vaibhavi\\AppData\\Roaming\\Python\\Python312\\site-packages\\pandas\\compat\\_optional.py\", line 135, in import_optional_dependency\n",
      "    module = importlib.import_module(name)\n",
      "  File \"C:\\Users\\vaibhavi\\anaconda3\\Lib\\importlib\\__init__.py\", line 90, in import_module\n",
      "    return _bootstrap._gcd_import(name[level:], package, level)\n",
      "  File \"C:\\Users\\vaibhavi\\anaconda3\\Lib\\site-packages\\numexpr\\__init__.py\", line 24, in <module>\n",
      "    from numexpr.interpreter import MAX_THREADS, use_vml, __BLOCK_SIZE1__\n"
     ]
    },
    {
     "ename": "AttributeError",
     "evalue": "_ARRAY_API not found",
     "output_type": "error",
     "traceback": [
      "\u001b[1;31m---------------------------------------------------------------------------\u001b[0m",
      "\u001b[1;31mAttributeError\u001b[0m                            Traceback (most recent call last)",
      "\u001b[1;31mAttributeError\u001b[0m: _ARRAY_API not found"
     ]
    },
    {
     "name": "stderr",
     "output_type": "stream",
     "text": [
      "\n",
      "A module that was compiled using NumPy 1.x cannot be run in\n",
      "NumPy 2.2.1 as it may crash. To support both 1.x and 2.x\n",
      "versions of NumPy, modules must be compiled with NumPy 2.0.\n",
      "Some module may need to rebuild instead e.g. with 'pybind11>=2.12'.\n",
      "\n",
      "If you are a user of the module, the easiest solution will be to\n",
      "downgrade to 'numpy<2' or try to upgrade the affected module.\n",
      "We expect that some modules will need time to support NumPy 2.\n",
      "\n",
      "Traceback (most recent call last):  File \"<frozen runpy>\", line 198, in _run_module_as_main\n",
      "  File \"<frozen runpy>\", line 88, in _run_code\n",
      "  File \"C:\\Users\\vaibhavi\\anaconda3\\Lib\\site-packages\\ipykernel_launcher.py\", line 17, in <module>\n",
      "    app.launch_new_instance()\n",
      "  File \"C:\\Users\\vaibhavi\\anaconda3\\Lib\\site-packages\\traitlets\\config\\application.py\", line 1075, in launch_instance\n",
      "    app.start()\n",
      "  File \"C:\\Users\\vaibhavi\\anaconda3\\Lib\\site-packages\\ipykernel\\kernelapp.py\", line 701, in start\n",
      "    self.io_loop.start()\n",
      "  File \"C:\\Users\\vaibhavi\\anaconda3\\Lib\\site-packages\\tornado\\platform\\asyncio.py\", line 205, in start\n",
      "    self.asyncio_loop.run_forever()\n",
      "  File \"C:\\Users\\vaibhavi\\anaconda3\\Lib\\asyncio\\windows_events.py\", line 322, in run_forever\n",
      "    super().run_forever()\n",
      "  File \"C:\\Users\\vaibhavi\\anaconda3\\Lib\\asyncio\\base_events.py\", line 641, in run_forever\n",
      "    self._run_once()\n",
      "  File \"C:\\Users\\vaibhavi\\anaconda3\\Lib\\asyncio\\base_events.py\", line 1986, in _run_once\n",
      "    handle._run()\n",
      "  File \"C:\\Users\\vaibhavi\\anaconda3\\Lib\\asyncio\\events.py\", line 88, in _run\n",
      "    self._context.run(self._callback, *self._args)\n",
      "  File \"C:\\Users\\vaibhavi\\anaconda3\\Lib\\site-packages\\ipykernel\\kernelbase.py\", line 534, in dispatch_queue\n",
      "    await self.process_one()\n",
      "  File \"C:\\Users\\vaibhavi\\anaconda3\\Lib\\site-packages\\ipykernel\\kernelbase.py\", line 523, in process_one\n",
      "    await dispatch(*args)\n",
      "  File \"C:\\Users\\vaibhavi\\anaconda3\\Lib\\site-packages\\ipykernel\\kernelbase.py\", line 429, in dispatch_shell\n",
      "    await result\n",
      "  File \"C:\\Users\\vaibhavi\\anaconda3\\Lib\\site-packages\\ipykernel\\kernelbase.py\", line 767, in execute_request\n",
      "    reply_content = await reply_content\n",
      "  File \"C:\\Users\\vaibhavi\\anaconda3\\Lib\\site-packages\\ipykernel\\ipkernel.py\", line 429, in do_execute\n",
      "    res = shell.run_cell(\n",
      "  File \"C:\\Users\\vaibhavi\\anaconda3\\Lib\\site-packages\\ipykernel\\zmqshell.py\", line 549, in run_cell\n",
      "    return super().run_cell(*args, **kwargs)\n",
      "  File \"C:\\Users\\vaibhavi\\anaconda3\\Lib\\site-packages\\IPython\\core\\interactiveshell.py\", line 3075, in run_cell\n",
      "    result = self._run_cell(\n",
      "  File \"C:\\Users\\vaibhavi\\anaconda3\\Lib\\site-packages\\IPython\\core\\interactiveshell.py\", line 3130, in _run_cell\n",
      "    result = runner(coro)\n",
      "  File \"C:\\Users\\vaibhavi\\anaconda3\\Lib\\site-packages\\IPython\\core\\async_helpers.py\", line 128, in _pseudo_sync_runner\n",
      "    coro.send(None)\n",
      "  File \"C:\\Users\\vaibhavi\\anaconda3\\Lib\\site-packages\\IPython\\core\\interactiveshell.py\", line 3334, in run_cell_async\n",
      "    has_raised = await self.run_ast_nodes(code_ast.body, cell_name,\n",
      "  File \"C:\\Users\\vaibhavi\\anaconda3\\Lib\\site-packages\\IPython\\core\\interactiveshell.py\", line 3517, in run_ast_nodes\n",
      "    if await self.run_code(code, result, async_=asy):\n",
      "  File \"C:\\Users\\vaibhavi\\anaconda3\\Lib\\site-packages\\IPython\\core\\interactiveshell.py\", line 3577, in run_code\n",
      "    exec(code_obj, self.user_global_ns, self.user_ns)\n",
      "  File \"C:\\Users\\vaibhavi\\AppData\\Local\\Temp\\ipykernel_27692\\3143499411.py\", line 5, in <module>\n",
      "    import pandas as pd\n",
      "  File \"C:\\Users\\vaibhavi\\AppData\\Roaming\\Python\\Python312\\site-packages\\pandas\\__init__.py\", line 62, in <module>\n",
      "    from pandas.core.api import (\n",
      "  File \"C:\\Users\\vaibhavi\\AppData\\Roaming\\Python\\Python312\\site-packages\\pandas\\core\\api.py\", line 28, in <module>\n",
      "    from pandas.core.arrays import Categorical\n",
      "  File \"C:\\Users\\vaibhavi\\AppData\\Roaming\\Python\\Python312\\site-packages\\pandas\\core\\arrays\\__init__.py\", line 1, in <module>\n",
      "    from pandas.core.arrays.arrow import ArrowExtensionArray\n",
      "  File \"C:\\Users\\vaibhavi\\AppData\\Roaming\\Python\\Python312\\site-packages\\pandas\\core\\arrays\\arrow\\__init__.py\", line 5, in <module>\n",
      "    from pandas.core.arrays.arrow.array import ArrowExtensionArray\n",
      "  File \"C:\\Users\\vaibhavi\\AppData\\Roaming\\Python\\Python312\\site-packages\\pandas\\core\\arrays\\arrow\\array.py\", line 64, in <module>\n",
      "    from pandas.core.arrays.masked import BaseMaskedArray\n",
      "  File \"C:\\Users\\vaibhavi\\AppData\\Roaming\\Python\\Python312\\site-packages\\pandas\\core\\arrays\\masked.py\", line 60, in <module>\n",
      "    from pandas.core import (\n",
      "  File \"C:\\Users\\vaibhavi\\AppData\\Roaming\\Python\\Python312\\site-packages\\pandas\\core\\nanops.py\", line 52, in <module>\n",
      "    bn = import_optional_dependency(\"bottleneck\", errors=\"warn\")\n",
      "  File \"C:\\Users\\vaibhavi\\AppData\\Roaming\\Python\\Python312\\site-packages\\pandas\\compat\\_optional.py\", line 135, in import_optional_dependency\n",
      "    module = importlib.import_module(name)\n",
      "  File \"C:\\Users\\vaibhavi\\anaconda3\\Lib\\importlib\\__init__.py\", line 90, in import_module\n",
      "    return _bootstrap._gcd_import(name[level:], package, level)\n",
      "  File \"C:\\Users\\vaibhavi\\anaconda3\\Lib\\site-packages\\bottleneck\\__init__.py\", line 7, in <module>\n",
      "    from .move import (move_argmax, move_argmin, move_max, move_mean, move_median,\n"
     ]
    },
    {
     "ename": "ImportError",
     "evalue": "\nA module that was compiled using NumPy 1.x cannot be run in\nNumPy 2.2.1 as it may crash. To support both 1.x and 2.x\nversions of NumPy, modules must be compiled with NumPy 2.0.\nSome module may need to rebuild instead e.g. with 'pybind11>=2.12'.\n\nIf you are a user of the module, the easiest solution will be to\ndowngrade to 'numpy<2' or try to upgrade the affected module.\nWe expect that some modules will need time to support NumPy 2.\n\n",
     "output_type": "error",
     "traceback": [
      "\u001b[1;31m---------------------------------------------------------------------------\u001b[0m",
      "\u001b[1;31mImportError\u001b[0m                               Traceback (most recent call last)",
      "File \u001b[1;32m~\\AppData\\Roaming\\Python\\Python312\\site-packages\\numpy\\core\\_multiarray_umath.py:44\u001b[0m, in \u001b[0;36m__getattr__\u001b[1;34m(attr_name)\u001b[0m\n\u001b[0;32m     39\u001b[0m     \u001b[38;5;66;03m# Also print the message (with traceback).  This is because old versions\u001b[39;00m\n\u001b[0;32m     40\u001b[0m     \u001b[38;5;66;03m# of NumPy unfortunately set up the import to replace (and hide) the\u001b[39;00m\n\u001b[0;32m     41\u001b[0m     \u001b[38;5;66;03m# error.  The traceback shouldn't be needed, but e.g. pytest plugins\u001b[39;00m\n\u001b[0;32m     42\u001b[0m     \u001b[38;5;66;03m# seem to swallow it and we should be failing anyway...\u001b[39;00m\n\u001b[0;32m     43\u001b[0m     sys\u001b[38;5;241m.\u001b[39mstderr\u001b[38;5;241m.\u001b[39mwrite(msg \u001b[38;5;241m+\u001b[39m tb_msg)\n\u001b[1;32m---> 44\u001b[0m     \u001b[38;5;28;01mraise\u001b[39;00m \u001b[38;5;167;01mImportError\u001b[39;00m(msg)\n\u001b[0;32m     46\u001b[0m ret \u001b[38;5;241m=\u001b[39m \u001b[38;5;28mgetattr\u001b[39m(_multiarray_umath, attr_name, \u001b[38;5;28;01mNone\u001b[39;00m)\n\u001b[0;32m     47\u001b[0m \u001b[38;5;28;01mif\u001b[39;00m ret \u001b[38;5;129;01mis\u001b[39;00m \u001b[38;5;28;01mNone\u001b[39;00m:\n",
      "\u001b[1;31mImportError\u001b[0m: \nA module that was compiled using NumPy 1.x cannot be run in\nNumPy 2.2.1 as it may crash. To support both 1.x and 2.x\nversions of NumPy, modules must be compiled with NumPy 2.0.\nSome module may need to rebuild instead e.g. with 'pybind11>=2.12'.\n\nIf you are a user of the module, the easiest solution will be to\ndowngrade to 'numpy<2' or try to upgrade the affected module.\nWe expect that some modules will need time to support NumPy 2.\n\n"
     ]
    },
    {
     "ename": "NameError",
     "evalue": "name 'request' is not defined",
     "output_type": "error",
     "traceback": [
      "\u001b[1;31m---------------------------------------------------------------------------\u001b[0m",
      "\u001b[1;31mNameError\u001b[0m                                 Traceback (most recent call last)",
      "Cell \u001b[1;32mIn[1], line 11\u001b[0m\n\u001b[0;32m      8\u001b[0m url \u001b[38;5;241m=\u001b[39m \u001b[38;5;124m'\u001b[39m\u001b[38;5;124mhttps://www.aajtak.in/\u001b[39m\u001b[38;5;124m'\u001b[39m\n\u001b[0;32m     10\u001b[0m \u001b[38;5;66;03m#send HTTP GET request response \u001b[39;00m\n\u001b[1;32m---> 11\u001b[0m response\u001b[38;5;241m=\u001b[39m request\u001b[38;5;241m.\u001b[39mget(url)\n\u001b[0;32m     12\u001b[0m \u001b[38;5;124;03m''' \u001b[39;00m\n\u001b[0;32m     13\u001b[0m \u001b[38;5;124;03mNote = response =200 then it is successful to get data from url\u001b[39;00m\n\u001b[0;32m     14\u001b[0m \u001b[38;5;124;03m'''\u001b[39;00m\n\u001b[0;32m     15\u001b[0m \u001b[38;5;66;03m# check if request is successful\u001b[39;00m\n",
      "\u001b[1;31mNameError\u001b[0m: name 'request' is not defined"
     ]
    }
   ],
   "source": [
    "# Web Scrapping library for BeautifulSoup\n",
    "\n",
    "import requests as \n",
    "from bs4 import BeautifulSoup\n",
    "import pandas as pd\n",
    "from  datetime import datetime\n",
    "# Target URL news channel link\n",
    "url = 'https://www.aajtak.in/'\n",
    "\n",
    "#send HTTP GET request response \n",
    "response= request.get(url)\n",
    "''' \n",
    "Note = response =200 then it is successful to get data from url\n",
    "'''\n",
    "# check if request is successful\n",
    "if response.status_code == 200:\n",
    "    soup = BeautifulSoup(response.content,'html.parser')\n",
    "    # locate headlines  and output show real website heading\n",
    "\n",
    "    headlines_html = soup.find_all('h3') #adjust if needed change\n",
    "\n",
    "    # extract text from user/ tags\n",
    "    headlines = [h.get_text(strip=True)for h in headlines_html if h.get_text(string=True)]\n",
    "\n",
    "    # converting data into two or multidimentional array\n",
    "    df = pd.DataFrame({\n",
    "        'headline': headlines,\n",
    "        'source':url,\n",
    "        'scraped_time':datetime.now()\n",
    "    }) \n",
    "\n",
    "    print(df.head())\n",
    "\n",
    "    df.to_csv('aajtak_headlines.csv', index =False,encoding= 'utf-8-sig')\n",
    "    print('Saved to aajtak headlines.csv')\n",
    "else:\n",
    "    print('failed to retrieve msg .status code : ',response.status_code)\n",
    "\n"
   ]
  }
 ],
 "metadata": {
  "interpreter": {
   "hash": "fa4952b4b82c744d2eb9d1a5a155c393c2a1aa2440fc47eedccd8f89f2892a59"
  },
  "kernelspec": {
   "display_name": "Python 3.12.7 64-bit ('base': conda)",
   "name": "python3"
  },
  "language_info": {
   "codemirror_mode": {
    "name": "ipython",
    "version": 3
   },
   "file_extension": ".py",
   "mimetype": "text/x-python",
   "name": "python",
   "nbconvert_exporter": "python",
   "pygments_lexer": "ipython3",
   "version": "3.12.7"
  },
  "orig_nbformat": 4
 },
 "nbformat": 4,
 "nbformat_minor": 2
}
